<?xml version="1.0" ?>
<sdf version="1.10" xmlns:xsi="http://www.w3.org/2001/XMLSchema-instance">
    <world name="car_world">
        <physics name="1ms" type="ignored">
            <max_step_size>0.001</max_step_size>
            <real_time_factor>1.0</real_time_factor>
        </physics>
        <plugin
            filename="gz-sim-physics-system"
            name="gz::sim::systems::Physics">
        </plugin>
        <plugin
            filename="gz-sim-user-commands-system"
            name="gz::sim::systems::UserCommands">
        </plugin>
        <plugin
            filename="gz-sim-scene-broadcaster-system"
            name="gz::sim::systems::SceneBroadcaster">
        </plugin>

        <light type="directional" name="sun">
            <cast_shadows>true</cast_shadows>
            <pose>0 0 10 0 0 0</pose>
            <diffuse>0.8 0.8 0.8 1</diffuse>
            <specular>0.2 0.2 0.2 1</specular>
            <attenuation>
                <range>1000</range>
                <constant>0.9</constant>
                <linear>0.01</linear>
                <quadratic>0.001</quadratic>
            </attenuation>
            <direction>-0.5 0.1 -0.9</direction>
        </light>

        <model name="ground_plane">
            <static>true</static>
            <link name="link">
                <collision name="collision">
                <geometry>
                    <plane>
                    <normal>0 0 1</normal>
                    </plane>
                </geometry>
                </collision>
                <visual name="visual">
                <geometry>
                    <plane>
                    <normal>0 0 1</normal>
                    <size>100 100</size>
                    </plane>
                </geometry>
                <material>
                    <ambient>0.8 0.8 0.8 1</ambient>
                    <diffuse>0.8 0.8 0.8 1</diffuse>
                    <specular>0.8 0.8 0.8 1</specular>
                </material>
                </visual>
            </link>
        </model>

        <model name='sketch_follower' canonical_link='base'>
            <pose relative_to='world'>0 0 0 0 0 0</pose>

            <link name='base'>
                <pose relative_to='__model__'>0 0 0 0 0 0</pose>
                <inertial>
                    <mass>1.2</mass>
                    <inertia>
                        <ixx>0.248125</ixx>
                        <ixy>0</ixy>
                        <ixz>0</ixz>
                        <iyy>0.248125</iyy>
                        <iyz>0</iyz>
                        <izz>0.468125</izz>
                    </inertia>
                </inertial>

                <visual name='visual'>
                    <geometry>
                        <mesh>
                            <uri>./meshes/3d_base_link.stl</uri>
                            <scale>0.02 0.02 0.02</scale>
                        </mesh>
                    </geometry>
                    <material>
                        <ambient>0 0.5 1 1</ambient>
                        <diffuse>0 0.5 1 1</diffuse>
                        <specular>0 0.5 1 1</specular>
                    </material>
                </visual>

                <collision name='collision'>
                    <geometry>
                        <mesh>
                            <uri>./meshes/3d_base_link.stl</uri>
                            <scale>0.02 0.02 0.02</scale>
                        </mesh>
                    </geometry>
                </collision>
            </link>

            <link name='base_arm_slot'>
                <pose relative_to='base'>0 0 0.6 0 0 0</pose>
                <inertial>
                    <mass>1.2</mass>
                    <inertia>
                        <ixx>0.1884564</ixx>
                        <ixy>0</ixy>
                        <ixz>0</ixz>
                        <iyy>0.1884564</iyy>
                        <iyz>0</iyz>
                        <izz>0.2684564</izz>
                    </inertia>
                </inertial>

                <visual name='visual'>
                    <geometry>
                        <mesh>
                            <uri>./meshes/3d_base_arm_slot.stl</uri>
                            <scale>0.02 0.02 0.02</scale>
                        </mesh>
                    </geometry>
                    <material>
                        <ambient>0 1 0.5 1</ambient>
                        <diffuse>0 1 0.5 1</diffuse>
                        <specular>0 1 0.5 1</specular>
                    </material>
                </visual>

                <collision name='collision'>
                    <geometry>
                        <mesh>
                            <uri>./meshes/3d_base_arm_slot.stl</uri>
                            <scale>0.02 0.02 0.02</scale>
                        </mesh>
                    </geometry>
                </collision>
            </link>

            <joint name='base_arm_slot_joint' type='revolute'>
                <pose relative_to='base_arm_slot'/>
                <parent>base</parent>
                <child>base_arm_slot</child>
                <axis>
                    <xyz expressed_in='__model__'>0 0 1</xyz>
                    <limit>
                        <lower>-3.141592</lower>
                        <upper>3.141592</upper>
                    </limit>
                    <dynamics>
                        <damping>2</damping>
                        <friction>2</friction>
                    </dynamics>
                </axis>
            </joint>

            <link name='arm_link_1'>
                <pose relative_to='base_arm_slot'>0 -0.1 0.8 1.57079 0 3.141592</pose>
                <inertial>
                    <mass>1.2</mass>
                    <inertia>
                        <ixx>0.10025</ixx>
                        <ixy>0</ixy>
                        <ixz>0</ixz>
                        <iyy>0.017927</iyy>
                        <iyz>0</iyz>
                        <izz>0.11767</izz>
                    </inertia>
                </inertial>

                <visual name='visual'>
                    <geometry>
                        <mesh>
                            <uri>./meshes/3d_arm_link.stl</uri>
                            <scale>0.02 0.02 0.02</scale>
                        </mesh>
                    </geometry>
                    <material>
                        <ambient>1 0.5 0.5 1</ambient>
                        <diffuse>1 0.5 0.5 1</diffuse>
                        <specular>1 0.5 0.5 1</specular>
                    </material>
                </visual>

                <collision name='collision'>
                    <geometry>
                        <mesh>
                            <uri>./meshes/3d_arm_link.stl</uri>
                            <scale>0.02 0.02 0.02</scale>
                        </mesh>
                    </geometry>
                </collision>
            </link>

            <joint name='arm_link_1_joint' type='revolute'>
                <pose relative_to='arm_link_1'/>
                <parent>base_arm_slot</parent>
                <child>arm_link_1</child>
                <axis>
                    <xyz expressed_in='__model__'>0 1 0</xyz>
                    <limit>
                        <lower>-3.141592</lower>
                        <upper>3.141592</upper>
                    </limit>
                    <dynamics>
                        <damping>2</damping>
                        <friction>2</friction>
                    </dynamics>
                </axis>    
            </joint>

            <link name='arm_link_2'>
                <pose relative_to='arm_link_1'>0 2 0.4 0 3.141592 0</pose>
                <inertial>
                    <mass>1.2</mass>
                    <inertia>
                        <ixx>0.10025</ixx>
                        <ixy>0</ixy>
                        <ixz>0</ixz>
                        <iyy>0.017927</iyy>
                        <iyz>0</iyz>
                        <izz>0.11767</izz>
                    </inertia>
                </inertial>

                <visual name='visual'>
                    <geometry>
                        <mesh>
                            <uri>./meshes/3d_arm_link.stl</uri>
                            <scale>0.02 0.02 0.02</scale>
                        </mesh>
                    </geometry>
                    <material>
                        <ambient>0.8 0 1 1</ambient>
                        <diffuse>0.8 0 1 1</diffuse>
                        <specular>0.8 0 1 1</specular>
                    </material>
                </visual>

                <collision name='collision'>
                    <geometry>
                        <mesh>
                            <uri>./meshes/3d_arm_link.stl</uri>
                            <scale>0.02 0.02 0.02</scale>
                        </mesh>
                    </geometry>
                </collision>
            </link>

            <joint name='arm_link_2_joint' type='revolute'>
                <pose relative_to='arm_link_2'/>
                <parent>arm_link_1</parent>
                <child>arm_link_2</child>
                <axis>
                    <xyz expressed_in='__model__'>0 1 0</xyz>
                    <limit>
                        <lower>-3.141592</lower>
                        <upper>3.141592</upper>
                    </limit>
                    <dynamics>
                        <damping>2</damping>
                        <friction>2</friction>
                    </dynamics>
                </axis>
            </joint>

            <link name='end_effector'>
                <!-- <pose relative_to='arm_link_2'>0 2 0 0 0 0</pose> -->
                <pose relative_to='arm_link_2'>0 2 0.4 0 3.141592 0</pose>
                <inertial>
                    <mass>1.2</mass>
                    <inertia>
                        <ixx>0.169314</ixx>
                        <ixy>0</ixy>
                        <ixz>0</ixz>
                        <iyy>0.2</iyy>
                        <iyz>0</iyz>
                        <izz>0.116</izz>
                    </inertia>
                </inertial>

                <visual name='visual'>
                    <geometry>
                        <mesh>
                            <uri>./meshes/3d_end_effector.stl</uri>
                            <scale>0.02 0.02 0.02</scale>
                        </mesh>
                    </geometry>
                    <material>
                        <ambient>0 0.5 1 1</ambient>
                        <diffuse>0 0.5 1 1</diffuse>
                        <specular>0 0.5 1 1</specular>
                    </material>
                </visual>

                <collision name='collision'>
                    <geometry>
                        <mesh>
                            <uri>./meshes/3d_end_effector.stl</uri>
                            <scale>0.02 0.02 0.02</scale>
                        </mesh>
                    </geometry>
                </collision>
            </link>

            <joint name='end_effector_joint' type='revolute'>
                <pose relative_to='end_effector'/>
                <parent>arm_link_2</parent>
                <child>end_effector</child>
                <axis>
                    <xyz expressed_in='__model__'>0 1 0</xyz>
                    <limit>
                        <lower>-3.141592</lower>
                        <upper>3.141592</upper>
                    </limit>
                    <dynamics>
                        <damping>2</damping>
                        <friction>2</friction>
                    </dynamics>
                </axis>
            </joint>
        </model>
    </world>
</sdf>