<?xml version="1.0"?>
<robot xmlns:xacro="http://www.ros.org/wiki/xacro" name="robot_arm">
    <xacro:include filename="$(find sketch_follower)/robot_description/urdf/helpers.xacro"/>
    
    <gazebo>
        <plugin filename="libgazebo_ros_control.so" name="gazebo_ros_control" />
    </gazebo>

    <link name="world" />

    <link name="base_link">
        <xacro:inertial m="1.2" x="0.75" y="0.75" z="0.8" oy="0" oz="0.4" />
        <visual>
            <origin xyz="0.0 0.0 0.0" rpy="0 0.0 0.0"/>
            <geometry>
                 <mesh filename="package://sketch_follower/robot_description/meshes/base_link.stl" scale="${sf} ${sf} ${sf}"/>
            </geometry>
            <material name="blue" />
        </visual>
        <collision>
            <origin xyz="0.0 0.0 0.0" rpy="0.0 0.0 0.0"/>
            <geometry>
                 <mesh filename="package://sketch_follower/robot_description/meshes/base_link.stl" scale="${sf} ${sf} ${sf}"/>
            </geometry>
        </collision>
    </link>

    <gazebo reference="base_link">
        <material>Gazebo/White</material>
    </gazebo>

    <joint name="base_joint" type="fixed">
        <origin xyz="0.0 0.0 0" rpy="0.0 0.0 0.0"/>
        <parent link="world"/>
        <child link="base_link"/>
    </joint>

    <xacro:link index="0" material="green" />

    <gazebo reference="link_0">
        <material>Gazebo/Black</material>
    </gazebo>

    <joint name="link_0_joint" type="continuous">
        <origin xyz="0 0.0 0.55" rpy="0.0 0.0 0.0"/>
        <parent link="base_link"/>
        <child link="link_0"/>
        <axis xyz="0.0 0.0 1.0"/>
        <dynamics damping="2.0" friction="2.0"/>
    </joint>
    
    <xacro:transmission name="link_0_joint" />

    <xacro:link index="1" material="red" />
    
    <gazebo reference="link_1">
        <material>Gazebo/White</material>
    </gazebo>

    <joint name="link_1_joint" type="continuous">
        <origin xyz="0 1.51 0.1" rpy="0.0 0.0 0.0"/>
        <parent link="link_0"/>
        <child link="link_1"/>
        <axis xyz="0.0 0.0 1.0"/>
        <dynamics damping="2.0" friction="2.0"/>
    </joint>
    
    <xacro:transmission name="link_1_joint" />

    <xacro:link index="2" material="purple" />
    
    <gazebo reference="link_2">
        <material>Gazebo/Black</material>
    </gazebo>

    <joint name="link_2_joint" type="continuous">
        <origin xyz="0 1.51 0.1" rpy="0.0 0.0 0.0"/>
        <parent link="link_1"/>
        <child link="link_2"/>
        <axis xyz="0.0 0.0 1.0"/>
        <dynamics damping="2.0" friction="2.0"/>
    </joint>

    <xacro:transmission name="link_2_joint" />

    <link name="sketch_follower">
        <visual>
            <origin xyz="0.0 0.0 0.0" rpy="0.0 0.0 0.0"/>
            <geometry>
                <cylinder radius="0.2" length="0.05"/>
                <material name="green" />
            </geometry>
        </visual>
        <collision>
            <geometry>
                <cylinder radius="0.05" length="0.05"/>
            </geometry>
        </collision>
    </link>

    <gazebo reference="sketch_follower">
        <material>Gazebo/White</material>
    </gazebo>

    <joint name="sketch_follower_joint" type="fixed">
        <parent link="link_2"/>
        <child link="sketch_follower"/>
        <origin xyz="0.0 1.5 0" rpy="0.0 0.0 0.0"/>
    </joint>

    <link name="pen">
        <visual>
            <origin xyz="0.0 0.0 0.0" rpy="0.0 0.0 0.0"/>
            <geometry>
                <cylinder radius="0.05" length="0.8"/>
                <material name="green" />
            </geometry>
        </visual>
        <collision>
            <geometry>
                <cylinder radius="0.05" length="0.8"/>
            </geometry>
        </collision>
    </link>

    <gazebo reference="pen">
        <material>Gazebo/White</material>
    </gazebo>

    <joint name="pen_joint" type="fixed">
        <parent link="sketch_follower"/>
        <child link="pen"/>
        <origin xyz="0.0 0 -0.3" rpy="0.0 0.0 0.0"/>
    </joint>
    

</robot>