<?xml version="1.0" ?>
<!-- =================================================================================== -->
<!-- |    This document was autogenerated by xacro from /home/khaled/catkin_ws/src/sketch-follower_ros/sketch_follower_moveit/robot_description/urdf/2d_2dof.xacro | -->
<!-- |    EDITING THIS FILE BY HAND IS NOT RECOMMENDED                                 | -->
<!-- =================================================================================== -->
<robot name="sketch_follower_2d_2dof">
    <material name="blue">
        <color rgba="0 0.5 1 1" />
    </material>
    <material name="green">
        <color rgba="0 1 0.5 1" />
    </material>
    <material name="red">
        <color rgba="1 0.5 0.5 1" />
    </material>
    <material name="purple">
        <color rgba="0.8 0 1 1" />
    </material>
    <gazebo>
        <plugin filename="libgazebo_ros_control.so" name="gazebo_ros_control">
            <robotNamespace>/</robotNamespace>
        </plugin>
    </gazebo>
    <link name="world" />
    <link name="base_link">
        <inertial>
            <origin rpy="0.0 0.0 0.0" xyz="0 0 0.4" />
            <mass value="1.2" />
            <inertia ixx="0.12025" ixy="0.0" ixz="0.0" iyy="0.12025" iyz="0.0" izz="0.11249999999999999" />
        </inertial>
        <visual>
            <origin rpy="0 0.0 0.0" xyz="0.0 0.0 0.0" />
            <geometry>
                <mesh filename="package://sketch_follower/robot_description/meshes/base_link.stl" scale="0.005 0.005 0.005" />
            </geometry>
            <material name="blue" />
        </visual>
        <collision>
            <origin rpy="0.0 0.0 0.0" xyz="0.0 0.0 0.0" />
            <geometry>
                <mesh filename="package://sketch_follower/robot_description/meshes/base_link.stl" scale="0.005 0.005 0.005" />
            </geometry>
        </collision>
    </link>
    <gazebo reference="base_link">
        <material>Gazebo/White</material>
    </gazebo>
    <joint name="base_joint" type="fixed">
        <origin rpy="0.0 0.0 0.0" xyz="0.0 0.0 0" />
        <parent link="world" />
        <child link="base_link" />
    </joint>
    <link name="link_0">
        <inertial>
            <origin rpy="0.0 0.0 0.0" xyz="0 0.75 0.05" />
            <mass value="0.3" />
            <inertia ixx="0.10024999999999999" ixy="0.0" ixz="0.0" iyy="0.0065" iyz="0.0" izz="0.10625" />
        </inertial>
        <visual>
            <origin rpy="0.0 0.0 0.0" xyz="0 0.0 0.0" />
            <geometry>
                <mesh filename="package://sketch_follower/robot_description/meshes/link.stl" scale="0.005 0.005 0.005" />
            </geometry>
            <material name="green" />
        </visual>
        <collision>
            <origin rpy="0.0 0.0 0.0" xyz="0.0 0.0 0.0" />
            <geometry>
                <mesh filename="package://sketch_follower/robot_description/meshes/link.stl" scale="0.005 0.005 0.005" />
            </geometry>
        </collision>
    </link>
    <gazebo reference="link_0">
        <material>Gazebo/Black</material>
    </gazebo>
    <joint name="link_0_joint" type="continuous">
        <origin rpy="0.0 0.0 0.0" xyz="0 0.0 0.55" />
        <parent link="base_link" />
        <child link="link_0" />
        <axis xyz="0.0 0.0 1.0" />
        <dynamics damping="2.0" friction="2.0" />
    </joint>
    <transmission name="link_0_joint_transmission">
        <type>transmission_interface/SimpleTransmission</type>
        <joint name="link_0_joint">
            <hardwareInterface>hardware_interface/EffortJointInterface</hardwareInterface>
        </joint>
        <actuator name="link_0_joint_actuator">
            <hardwareInterface>hardware_interface/EffortJointInterface</hardwareInterface>
            <mechanicalReduction>1</mechanicalReduction>
        </actuator>
    </transmission>
    <link name="link_1">
        <inertial>
            <origin rpy="0.0 0.0 0.0" xyz="0 0.75 0.05" />
            <mass value="0.3" />
            <inertia ixx="0.10024999999999999" ixy="0.0" ixz="0.0" iyy="0.0065" iyz="0.0" izz="0.10625" />
        </inertial>
        <visual>
            <origin rpy="0.0 0.0 0.0" xyz="0 0.0 0.0" />
            <geometry>
                <mesh filename="package://sketch_follower/robot_description/meshes/link.stl" scale="0.005 0.005 0.005" />
            </geometry>
            <material name="red" />
        </visual>
        <collision>
            <origin rpy="0.0 0.0 0.0" xyz="0.0 0.0 0.0" />
            <geometry>
                <mesh filename="package://sketch_follower/robot_description/meshes/link.stl" scale="0.005 0.005 0.005" />
            </geometry>
        </collision>
    </link>
    <gazebo reference="link_1">
        <material>Gazebo/White</material>
    </gazebo>
    <joint name="link_1_joint" type="continuous">
        <origin rpy="0.0 0.0 0.0" xyz="0 1.51 0.1" />
        <parent link="link_0" />
        <child link="link_1" />
        <axis xyz="0.0 0.0 1.0" />
        <dynamics damping="2.0" friction="2.0" />
    </joint>
    <transmission name="link_1_joint_transmission">
        <type>transmission_interface/SimpleTransmission</type>
        <joint name="link_1_joint">
            <hardwareInterface>hardware_interface/EffortJointInterface</hardwareInterface>
        </joint>
        <actuator name="link_1_joint_actuator">
            <hardwareInterface>hardware_interface/EffortJointInterface</hardwareInterface>
            <mechanicalReduction>1</mechanicalReduction>
        </actuator>
    </transmission>
    <link name="sketch_follower">
        <visual>
            <origin rpy="0.0 0.0 0.0" xyz="0.0 0.0 0.0" />
            <geometry>
                <cylinder length="0.05" radius="0.2" />
                <material name="purple" />
            </geometry>
        </visual>
        <collision>
            <origin rpy="0.0 0.0 0.0" xyz="0.0 0.0 0.0" />
            <geometry>
                <cylinder length="0.05" radius="0.2" />
            </geometry>
        </collision>
        <inertial>
            <origin rpy="0.0 0.0 0.0" xyz="0.0 0.0 0.0" />
            <mass value="0.2" />
            <inertia ixx="0.0020416667" ixy="0.0" ixz="0.0" iyy="0.0020416667" iyz="0.0" izz="0.004" />
        </inertial>
    </link>
    <gazebo reference="sketch_follower">
        <material>Gazebo/Black</material>
    </gazebo>
    <joint name="sketch_follower_joint" type="continuous">
        <parent link="link_1" />
        <child link="sketch_follower" />
        <origin rpy="0.0 0.0 0.0" xyz="0.0 1.5 0" />
        <axis xyz="0.0 0.0 1.0" />
        <dynamics damping="3.0" friction="3.0" />
    </joint>
    <transmission name="sketch_follower_joint_transmission">
        <type>transmission_interface/SimpleTransmission</type>
        <joint name="sketch_follower_joint">
            <hardwareInterface>hardware_interface/EffortJointInterface</hardwareInterface>
        </joint>
        <actuator name="sketch_follower_joint_actuator">
            <hardwareInterface>hardware_interface/EffortJointInterface</hardwareInterface>
            <mechanicalReduction>1</mechanicalReduction>
        </actuator>
    </transmission>
    <link name="pen">
        <visual>
            <origin rpy="0.0 0.0 0.0" xyz="0.0 0.0 0.0" />
            <geometry>
                <cylinder length="0.6" radius="0.05" />
                <material name="purple" />
            </geometry>
        </visual>
        <collision>
            <geometry>
                <cylinder length="0.6" radius="0.05" />
            </geometry>
        </collision>
        <inertial>
            <mass value="0.1" />
            <origin xyz="0 0 0" rpy="0 0 0" />
            <inertia ixx="0.03" iyy="0.03" izz="0.03" ixy="0.0" ixz="0.0" iyz="0.0" />
        </inertial>
    </link>
    <gazebo reference="pen">
        <material>Gazebo/Black</material>
    </gazebo>
    <joint name="pen_joint" type="fixed">
        <parent link="sketch_follower" />
        <child link="pen" />
        <origin rpy="0.0 0.0 0.0" xyz="0.0 0 -0.3" />
    </joint>
</robot>

